2025-08-18 14:05:57,850 INFO    MainThread:159437 [wandb_setup.py:_flush():79] Current SDK version is 0.18.3
2025-08-18 14:05:57,850 INFO    MainThread:159437 [wandb_setup.py:_flush():79] Configure stats pid to 159437
2025-08-18 14:05:57,850 INFO    MainThread:159437 [wandb_setup.py:_flush():79] Loading settings from /home/user/.config/wandb/settings
2025-08-18 14:05:57,850 INFO    MainThread:159437 [wandb_setup.py:_flush():79] Loading settings from /home/user/workspace/minimind/trainer/wandb/settings
2025-08-18 14:05:57,850 INFO    MainThread:159437 [wandb_setup.py:_flush():79] Loading settings from environment variables: {}
2025-08-18 14:05:57,850 INFO    MainThread:159437 [wandb_setup.py:_flush():79] Applying setup settings: {'mode': None, '_disable_service': None}
2025-08-18 14:05:57,850 INFO    MainThread:159437 [wandb_setup.py:_flush():79] Inferring run settings from compute environment: {'program_relpath': 'trainer/train_full_sft.py', 'program_abspath': '/home/user/workspace/minimind/trainer/train_full_sft.py', 'program': '/home/user/workspace/minimind/trainer/train_full_sft.py'}
2025-08-18 14:05:57,850 INFO    MainThread:159437 [wandb_setup.py:_flush():79] Applying login settings: {}
2025-08-18 14:05:57,850 INFO    MainThread:159437 [wandb_init.py:_log_setup():532] Logging user logs to /home/user/workspace/minimind/trainer/wandb/run-20250818_140557-73xitzoo/logs/debug.log
2025-08-18 14:05:57,850 INFO    MainThread:159437 [wandb_init.py:_log_setup():533] Logging internal logs to /home/user/workspace/minimind/trainer/wandb/run-20250818_140557-73xitzoo/logs/debug-internal.log
2025-08-18 14:05:57,850 INFO    MainThread:159437 [wandb_init.py:init():617] calling init triggers
2025-08-18 14:05:57,850 INFO    MainThread:159437 [wandb_init.py:init():624] wandb.init called with sweep_config: {}
config: {}
2025-08-18 14:05:57,850 INFO    MainThread:159437 [wandb_init.py:init():667] starting backend
2025-08-18 14:05:57,850 INFO    MainThread:159437 [wandb_init.py:init():671] sending inform_init request
2025-08-18 14:05:57,851 INFO    MainThread:159437 [backend.py:_multiprocessing_setup():104] multiprocessing start_methods=fork,spawn,forkserver, using: spawn
2025-08-18 14:05:57,852 INFO    MainThread:159437 [wandb_init.py:init():684] backend started and connected
2025-08-18 14:05:57,853 INFO    MainThread:159437 [wandb_init.py:init():779] updated telemetry
2025-08-18 14:05:57,859 INFO    MainThread:159437 [wandb_init.py:init():812] communicating run to backend with 90.0 second timeout
2025-08-18 14:06:56,270 INFO    Thread-1 (wrapped_target):159437 [retry.py:__call__():172] Retry attempt failed:
Traceback (most recent call last):
  File "/home/user/.virtualenvs/minimind/lib/python3.12/site-packages/urllib3/connection.py", line 198, in _new_conn
    sock = connection.create_connection(
           ^^^^^^^^^^^^^^^^^^^^^^^^^^^^^
  File "/home/user/.virtualenvs/minimind/lib/python3.12/site-packages/urllib3/util/connection.py", line 85, in create_connection
    raise err
  File "/home/user/.virtualenvs/minimind/lib/python3.12/site-packages/urllib3/util/connection.py", line 73, in create_connection
    sock.connect(sa)
TimeoutError: timed out

The above exception was the direct cause of the following exception:

Traceback (most recent call last):
  File "/home/user/.virtualenvs/minimind/lib/python3.12/site-packages/urllib3/connectionpool.py", line 787, in urlopen
    response = self._make_request(
               ^^^^^^^^^^^^^^^^^^^
  File "/home/user/.virtualenvs/minimind/lib/python3.12/site-packages/urllib3/connectionpool.py", line 488, in _make_request
    raise new_e
  File "/home/user/.virtualenvs/minimind/lib/python3.12/site-packages/urllib3/connectionpool.py", line 464, in _make_request
    self._validate_conn(conn)
  File "/home/user/.virtualenvs/minimind/lib/python3.12/site-packages/urllib3/connectionpool.py", line 1093, in _validate_conn
    conn.connect()
  File "/home/user/.virtualenvs/minimind/lib/python3.12/site-packages/urllib3/connection.py", line 753, in connect
    self.sock = sock = self._new_conn()
                       ^^^^^^^^^^^^^^^^
  File "/home/user/.virtualenvs/minimind/lib/python3.12/site-packages/urllib3/connection.py", line 207, in _new_conn
    raise ConnectTimeoutError(
urllib3.exceptions.ConnectTimeoutError: (<urllib3.connection.HTTPSConnection object at 0x726ea643ebd0>, 'Connection to api.wandb.ai timed out. (connect timeout=20)')

The above exception was the direct cause of the following exception:

Traceback (most recent call last):
  File "/home/user/.virtualenvs/minimind/lib/python3.12/site-packages/requests/adapters.py", line 667, in send
    resp = conn.urlopen(
           ^^^^^^^^^^^^^
  File "/home/user/.virtualenvs/minimind/lib/python3.12/site-packages/urllib3/connectionpool.py", line 841, in urlopen
    retries = retries.increment(
              ^^^^^^^^^^^^^^^^^^
  File "/home/user/.virtualenvs/minimind/lib/python3.12/site-packages/urllib3/util/retry.py", line 519, in increment
    raise MaxRetryError(_pool, url, reason) from reason  # type: ignore[arg-type]
    ^^^^^^^^^^^^^^^^^^^^^^^^^^^^^^^^^^^^^^^^^^^^^^^^^^^
urllib3.exceptions.MaxRetryError: HTTPSConnectionPool(host='api.wandb.ai', port=443): Max retries exceeded with url: /graphql (Caused by ConnectTimeoutError(<urllib3.connection.HTTPSConnection object at 0x726ea643ebd0>, 'Connection to api.wandb.ai timed out. (connect timeout=20)'))

During handling of the above exception, another exception occurred:

Traceback (most recent call last):
  File "/home/user/.virtualenvs/minimind/lib/python3.12/site-packages/wandb/sdk/lib/retry.py", line 131, in __call__
    result = self._call_fn(*args, **kwargs)
             ^^^^^^^^^^^^^^^^^^^^^^^^^^^^^^
  File "/home/user/.virtualenvs/minimind/lib/python3.12/site-packages/wandb/sdk/internal/internal_api.py", line 347, in execute
    return self.client.execute(*args, **kwargs)  # type: ignore
           ^^^^^^^^^^^^^^^^^^^^^^^^^^^^^^^^^^^^
  File "/home/user/.virtualenvs/minimind/lib/python3.12/site-packages/wandb/vendor/gql-0.2.0/wandb_gql/client.py", line 52, in execute
    result = self._get_result(document, *args, **kwargs)
             ^^^^^^^^^^^^^^^^^^^^^^^^^^^^^^^^^^^^^^^^^^^
  File "/home/user/.virtualenvs/minimind/lib/python3.12/site-packages/wandb/vendor/gql-0.2.0/wandb_gql/client.py", line 60, in _get_result
    return self.transport.execute(document, *args, **kwargs)
           ^^^^^^^^^^^^^^^^^^^^^^^^^^^^^^^^^^^^^^^^^^^^^^^^^
  File "/home/user/.virtualenvs/minimind/lib/python3.12/site-packages/wandb/sdk/lib/gql_request.py", line 58, in execute
    request = self.session.post(self.url, **post_args)
              ^^^^^^^^^^^^^^^^^^^^^^^^^^^^^^^^^^^^^^^^
  File "/home/user/.virtualenvs/minimind/lib/python3.12/site-packages/requests/sessions.py", line 637, in post
    return self.request("POST", url, data=data, json=json, **kwargs)
           ^^^^^^^^^^^^^^^^^^^^^^^^^^^^^^^^^^^^^^^^^^^^^^^^^^^^^^^^^
  File "/home/user/.virtualenvs/minimind/lib/python3.12/site-packages/requests/sessions.py", line 589, in request
    resp = self.send(prep, **send_kwargs)
           ^^^^^^^^^^^^^^^^^^^^^^^^^^^^^^
  File "/home/user/.virtualenvs/minimind/lib/python3.12/site-packages/requests/sessions.py", line 703, in send
    r = adapter.send(request, **kwargs)
        ^^^^^^^^^^^^^^^^^^^^^^^^^^^^^^^
  File "/home/user/.virtualenvs/minimind/lib/python3.12/site-packages/requests/adapters.py", line 688, in send
    raise ConnectTimeout(e, request=request)
requests.exceptions.ConnectTimeout: HTTPSConnectionPool(host='api.wandb.ai', port=443): Max retries exceeded with url: /graphql (Caused by ConnectTimeoutError(<urllib3.connection.HTTPSConnection object at 0x726ea643ebd0>, 'Connection to api.wandb.ai timed out. (connect timeout=20)'))
2025-08-18 14:07:27,889 ERROR   MainThread:159437 [wandb_init.py:init():838] encountered error: Run initialization has timed out after 90.0 sec. 
Please refer to the documentation for additional information: https://docs.wandb.ai/guides/track/tracking-faq#initstarterror-error-communicating-with-wandb-process-
2025-08-18 14:07:27,890 ERROR   MainThread:159437 [wandb_init.py:init():1262] error in wandb.init()
Traceback (most recent call last):
  File "/home/user/.virtualenvs/minimind/lib/python3.12/site-packages/wandb/sdk/wandb_init.py", line 1252, in init
    return wi.init()
           ^^^^^^^^^
  File "/home/user/.virtualenvs/minimind/lib/python3.12/site-packages/wandb/sdk/wandb_init.py", line 844, in init
    raise error
wandb.errors.errors.CommError: Run initialization has timed out after 90.0 sec. 
Please refer to the documentation for additional information: https://docs.wandb.ai/guides/track/tracking-faq#initstarterror-error-communicating-with-wandb-process-
2025-08-18 14:07:28,822 WARNING MsgRouterThr:159437 [router.py:message_loop():77] message_loop has been closed
